try:
    print("succeeding try")
finally:
    print("succeeding finally")

print("---------")

try:
    try:
        print("failing try")
        throw new VariableError("try error")
    finally:
        print("succeeding finally")
catch VariableError e:
    print("got error: {e}")

print("---------")

try:
    try:
        print("succeeding try")
    finally:
        print("failing finally")
        throw new VariableError("finally error")
catch VariableError e:
    print("got error: {e}")

print("---------")

try:
    try:
        print("failing try")
        # Currently this error gets discarded, will hopefully be fixed some day
        throw new VariableError("try error")
    finally:
        print("failing finally")
        throw new VariableError("finally error")
catch VariableError e:
    print("got error: {e}")
